Workbook

Sheet 1. Вводные
B1: ДНП «УСАДЬБА ЭРМИТАЖ» — МАСТЕР ДОПУЩЕНИЙ
B2: Редевелопмент поселка · 55 участков под ИЖС · Московская обл., Можайский р-н
B3: СИНИЙ текст = исходные данные (вводите здесь) | ЧЁРНЫЙ текст = формулы (не менять) | ЗЕЛЁНЫЙ = ссылки на другие листы
B5: 1. АКТИВ
B6: Параметр | C6: Значение | D6: Ед. изм. | E6: Примечание
B7: Общая площадь ДНП | C7: 10 | D7: га | E7: По договору аренды
B8: Всего участков | C8: 55 | D8: шт. | E8: По плану межевания
B9: Из них продаётся (редевелопмент) | C9: 55 | D9: шт. | E9: Все участки — стратегия полного выкупа
B10: Средняя площадь участка | C10: 15 | D10: соток | E10: Большинство 1 500 м², часть угловых до 1 856 м²
B11: Суммарная продаваемая площадь | C11: =C8*C10 -> 825 | D11: соток | E11: участков × средняя площадь
B12: Удалённость от МКАД | C12: 100 | D12: км | E12: Минское шоссе М-1
B13: Текущий статус земли | C13: Аренда 49 лет | E13: С правом перевода в собственность
B14: Природное окружение | C14: Заповедник Бородино | E14: Лес по всему периметру — ключевое УТП
B16: 2. ЦЕНООБРАЗОВАНИЕ
B17: Параметр | C17: Значение | D17: Ед. изм. | E17: Примечание
B18: Цена за сотку — фаза 1 (уч. 1–18) | C18: 85000 | D18: руб./сот. | E18: Дисконт 10% к рынку для разгона продаж
B19: Цена за сотку — фаза 2 (уч. 19–37) | C19: 105000 | D19: руб./сот. | E19: Рыночная цена после завершения инфраструктуры
B20: Цена за сотку — фаза 3 (уч. 38–55) | C20: 125000 | D20: руб./сот. | E20: Премиум после перевода земли в собственность
B21: Средневзвешенная цена за сотку | C21: =(C18*18+C19*19+C20*18)/55 -> 105000 | D21: руб./сот. | E21: Авт. расчёт
B22: Стоимость 1 участка (ср. взвеш.) | C22: =C21*C10 -> 1575000 | D22: руб. | E22: Средняя по портфелю
B23: Membershipvступительный взнос | C23: 50000 | D23: руб./уч. | E23: При подписании договора
B24: Целевой взнос (инфраструктура) | C24: 200000 | D24: руб./уч. | E24: На строительство общих объектов
B25: Ежегодный взнос (с 3-го года) | C25: 60000 | D25: руб./уч./год | E25: Управление, охрана, обслуживание
B27: 3. ТЕМП ПРОДАЖ
B28: Параметр | C28: Значение | D28: Ед. изм. | E28: Примечание
B29: Продажи — год 1 | C29: 8 | D29: уч./год | E29: Мягкий старт после достройки КПП
B30: Продажи — год 2 | C30: 14 | D30: уч./год | E30: Активная фаза — инфраструктура готова
B31: Продажи — год 3 | C31: 16 | D31: уч./год | E31: Пиковый год — перевод земли в собственность
B32: Продажи — год 4 | C32: 12 | D32: уч./год | E32: Финишная фаза
B33: Продажи — год 5 | C33: 5 | D33: уч./год | E33: Остаток
B34: Итого участков к продаже | C34: =C29+C30+C31+C32+C33 -> 55 | D34: уч. | E34: Должно быть 55
B36: 4. КАПИТАЛЬНЫЕ ВЛОЖЕНИЯ В ИНФРАСТРУКТУРУ
B37: Параметр | C37: Значение | D37: Ед. изм. | E37: Примечание
B38: Забор по периметру (5 км × 2 400 руб./м) | C38: 12000000 | D38: руб. | E38: Ориентир: профлист+бетон, 2 400 руб./пм
B39: КПП + шлагбаум + СКУД | C39: 3500000 | D39: руб. | E39: Дом охраны 50 м² + оборудование
B40: Административное здание (150 м²) | C40: 7500000 | D40: руб. | E40: 50 000 руб./м², отделка под ключ
B41: Пруд (противопожарный + рекреация) | C41: 4000000 | D41: руб. | E41: Выемка грунта + берегоукрепление
B42: Детская площадка + зона отдыха | C42: 1500000 | D42: руб. | E42: Оборудование + благоустройство
B43: Расширение дороги до 5,5 м + асфальт | C43: 8000000 | D43: руб. | E43: Критично для ИЖС, 800 руб./пм
B44: Электросети (35 кВт на участок) | C44: 5500000 | D44: руб. | E44: Трансформатор + разводка
...

Sheet 2. Денежный поток
B1: МОДЕЛЬ ДЕНЕЖНЫХ ПОТОКОВ · 55 участков · 5 лет
B2: Статья | C2: Год 1 | D2: Год 2 | E2: Год 3 | F2: Год 4 | G2: Год 5 | H2: ИТОГО
C3: 2025 | D3: 2026 | E3: 2027 | F3: 2028 | G3: 2029 | H3: 5 лет
B4: A. ОБЪЁМ ПРОДАЖ
B5: Участков продано в год (шт.) | C5: ='1. Вводные'!C29 -> 8 | D5: ='1. Вводные'!C30 -> 14 | E5: ='1. Вводные'!C31 -> 16 | F5: ='1. Вводные'!C32 -> 12 | G5: ='1. Вводные'!C33 -> 5 | H5: =SUM(C5:G5) -> 55
B6: Накопленные продажи (шт.) | C6: =C5 -> 8 | D6: =C6+D5 -> 22 | E6: =D6+E5 -> 38 | F6: =E6+F5 -> 50 | G6: =F6+G5 -> 55 | H6: =SUM(C6:G6) -> 173
B8: B. ДОХОДЫ (руб.)
B9: Выручка от продажи участков | C9: =C5*'1. Вводные'!C10*'1. Вводные'!C18 -> 10200000 | D9: =MIN(D5,MAX(0,18-C6))*'1. Вводные'!C10*'1. Вводные'!C18+MAX(0,D5-MAX(0,18-C6))*'1. Вводные'!C10*'1. Вводные'!C19 -> 19050000 | E9: =MAX(0,MIN(E5,MAX(0,37-D6)))*'1. Вводные'!C10*'1. Вводные'!C19+MAX(0,E5-MAX(0,37-D6))*'1. Вводные'!C10*'1. Вводные'!C20 -> 25500000 | F9: =MAX(0,MIN(F5,MAX(0,37-E6)))*'1. Вводные'!C10*'1. Вводные'!C19+MAX(0,F5-MAX(0,37-E6))*'1. Вводные'!C10*'1. Вводные'!C20 -> 22500000 | G9: =G5*'1. Вводные'!C10*'1. Вводные'!C20 -> 9375000 | H9: =SUM(C9:G9) -> 86625000
B10: Вступительные взносы (50 тыс./уч.) | C10: =C5*'1. Вводные'!C23 -> 400000 | D10: =D5*'1. Вводные'!C23 -> 700000 | E10: =E5*'1. Вводные'!C23 -> 800000 | F10: =F5*'1. Вводные'!C23 -> 600000 | G10: =G5*'1. Вводные'!C23 -> 250000 | H10: =SUM(C10:G10) -> 2750000
B11: Целевые взносы (200 тыс./уч.) | C11: =C5*'1. Вводные'!C24 -> 1600000 | D11: =D5*'1. Вводные'!C24 -> 2800000 | E11: =E5*'1. Вводные'!C24 -> 3200000 | F11: =F5*'1. Вводные'!C24 -> 2400000 | G11: =G5*'1. Вводные'!C24 -> 1000000 | H11: =SUM(C11:G11) -> 11000000
B12: Ежегодные членские взносы (60 тыс./уч.) | C12: =0 -> 0 | D12: =0 -> 0 | E12: =D6*'1. Вводные'!C25 -> 1320000 | F12: =E6*'1. Вводные'!C25 -> 2280000 | G12: =F6*'1. Вводные'!C25 -> 3000000 | H12: =SUM(C12:G12) -> 6600000
B13: ИТОГО ДОХОДЫ | C13: =C9+C10+C11+C12 -> 12200000 | D13: =D9+D10+D11+D12 -> 22550000 | E13: =E9+E10+E11+E12 -> 30820000 | F13: =F9+F10+F11+F12 -> 27780000 | G13: =G9+G10+G11+G12 -> 13625000 | H13: =SUM(C13:G13) -> 106975000
B15: C. КАПИТАЛЬНЫЕ ВЛОЖЕНИЯ (руб.)
B16: Забор по периметру | C16: ='1. Вводные'!C38 -> 12000000 | D16: =0 -> 0 | E16: =0 -> 0 | F16: =0 -> 0 | G16: =0 -> 0 | H16: =SUM(C16:G16) -> 12000000
B17: КПП + шлагбаум + СКУД | C17: ='1. Вводные'!C39 -> 3500000 | D17: =0 -> 0 | E17: =0 -> 0 | F17: =0 -> 0 | G17: =0 -> 0 | H17: =SUM(C17:G17) -> 3500000
B18: Административное здание | C18: ='1. Вводные'!C40*0.5 -> 3750000 | D18: ='1. Вводные'!C40*0.5 -> 3750000 | E18: =0 -> 0 | F18: =0 -> 0 | G18: =0 -> 0 | H18: =SUM(C18:G18) -> 7500000
B19: Пруд + детская площадка | C19: =('1. Вводные'!C41+'1. Вводные'!C42)*0.5 -> 2750000 | D19: =('1. Вводные'!C41+'1. Вводные'!C42)*0.5 -> 2750000 | E19: =0 -> 0 | F19: =0 -> 0 | G19: =0 -> 0 | H19: =SUM(C19:G19) -> 5500000
B20: Дороги + асфальтирование | C20: ='1. Вводные'!C43*0.5 -> 4000000 | D20: ='1. Вводные'!C43*0.5 -> 4000000 | E20: =0 -> 0 | F20: =0 -> 0 | G20: =0 -> 0 | H20: =SUM(C20:G20) -> 8000000
B21: Электросети | C21: ='1. Вводные'!C44 -> 5500000 | D21: =0 -> 0 | E21: =0 -> 0 | F21: =0 -> 0 | G21: =0 -> 0 | H21: =SUM(C21:G21) -> 5500000
B22: Ливнёвка + дренаж | C22: =0 -> 0 | D22: ='1. Вводные'!C45 -> 3000000 | E22: =0 -> 0 | F22: =0 -> 0 | G22: =0 -> 0 | H22: =SUM(C22:G22) -> 3000000
B23: Резерв capex (15%) | C23: ='1. Вводные'!C46*0.5 -> 3375000 | D23: ='1. Вводные'!C46*0.5 -> 3375000 | E23: =0 -> 0 | F23: =0 -> 0 | G23: =0 -> 0 | H23: =SUM(C23:G23) -> 6750000
B24: ИТОГО CAPEX | C24: =SUM(C16:C23) -> 34875000 | D24: =SUM(D16:D23) -> 16875000 | E24: =SUM(E16:E23) -> 0 | F24: =SUM(F16:F23) -> 0 | G24: =SUM(G16:G23) -> 0 | H24: =SUM(C24:G24) -> 51750000
B26: D. ОПЕРАЦИОННЫЕ РАСХОДЫ (руб.)
B27: Охрана 24/7 | C27: ='1. Вводные'!C51 -> 2400000 | D27: ='1. Вводные'!C51 -> 2400000 | E27: ='1. Вводные'!C51 -> 2400000 | F27: ='1. Вводные'!C51 -> 2400000 | G27: ='1. Вводные'!C51 -> 2400000 | H27: =SUM(C27:G27) -> 12000000
B28: Маркетинг и продажи | C28: ='1. Вводные'!C52 -> 3000000 | D28: ='1. Вводные'!C52 -> 3000000 | E28: ='1. Вводные'!C52 -> 3000000 | F28: ='1. Вводные'!C52 -> 3000000 | G28: ='1. Вводные'!C52 -> 3000000 | H28: =SUM(C28:G28) -> 15000000
B29: Обслуживание дорог, уборка | C29: ='1. Вводные'!C53 -> 800000 | D29: ='1. Вводные'!C53 -> 800000 | E29: ='1. Вводные'!C53 -> 800000 | F29: ='1. Вводные'!C53 -> 800000 | G29: ='1. Вводные'!C53 -> 800000 | H29: =SUM(C29:G29) -> 4000000
B30: Юридика + перевод земли | C30: ='1. Вводные'!C54 -> 1200000 | D30: ='1. Вводные'!C54 -> 1200000 | E30: ='1. Вводные'!C54 -> 1200000 | F30: ='1. Вводные'!C54 -> 1200000 | G30: ='1. Вводные'!C54 -> 1200000 | H30: =SUM(C30:G30) -> 6000000
B31: Управление ДНП (УК) | C31: ='1. Вводные'!C55 -> 1800000 | D31: ='1. Вводные'!C55 -> 1800000 | E31: ='1. Вводные'!C55 -> 1800000 | F31: ='1. Вводные'!C55 -> 1800000 | G31: ='1. Вводные'!C55 -> 1800000 | H31: =SUM(C31:G31) -> 9000000
B32: Прочие операционные | C32: ='1. Вводные'!C56 -> 600000 | D32: ='1. Вводные'!C56 -> 600000 | E32: ='1. Вводные'!C56 -> 600000 | F32: ='1. Вводные'!C56 -> 600000 | G32: ='1. Вводные'!C56 -> 600000 | H32: =SUM(C32:G32) -> 3000000
B33: ИТОГО OPEX | C33: =C27+C28+C29+C30+C31+C32 -> 9800000 | D33: =D27+D28+D29+D30+D31+D32 -> 9800000 | E33: =E27+E28+E29+E30+E31+E32 -> 9800000 | F33: =F27+F28+F29+F30+F31+F32 -> 9800000 | G33: =G27+G28+G29+G30+G31+G32 -> 9800000 | H33: =SUM(C33:G33) -> 49000000
B35: E. НАЛОГ (УСН 15% от прибыли)
B36: Налог на прибыль (УСН 15%) | C36: =MAX(0,(C13-C24-C33)*'1. Вводные'!C63) -> 0 | D36: =MAX(0,(D13-D24-D33)*'1. Вводные'!C63) -> 0 | E36: =MAX(0,(E13-E24-E33)*'1. Вводные'!C63) -> 3153000 | F36: =MAX(0,(F13-F24-F33)*'1. Вводные'!C63) -> 2697000 | G36: =MAX(0,(G13-G24-G33)*'1. Вводные'!C63) -> 573750 | H36: =SUM(C36:G36) -> 6423750
B38: F. ИТОГОВЫЕ ПОТОКИ
B39: ЧИСТЫЙ ДЕНЕЖНЫЙ ПОТОК (ЧДП) | C39: =C13-C24-C33-C36 -> -32475000 | D39: =D13-D24-D33-D36 -> -4125000 | E39: =E13-E24-E33-E36 -> 17867000 | F39: =F13-F24-F33-F36 -> 15283000 | G39: =G13-G24-G33-G36 -> 3251250 | H39: =SUM(C39:G39) -> -198750
B40: Накопленный ЧДП (нарастающим) | C40: =C39 -> -32475000 | D40: =C39+D39 -> -36600000 | E40: =D39+E39 -> 13742000 | F40: =E39+F39 -> 33150000 | G40: =F39+G39 -> 18534250 | H40: =SUM(C40:G40) -> -3648750
B42: G. KPI ПРОЕКТА
B43: Суммарная выручка (5 лет) | C43: =H13 -> 106975000
B44: Суммарные расходы (CAPEX+OPEX+Налог) | C44: =H24+H33+H36 -> 107173750
B45: Чистая прибыль | C45: =H39 -> -198750
B46: ROI (прибыль/затраты) | C46: =H39/(H24+H33) -> -0.0019727047
...

Sheet 3. Сценарии
B1: СЦЕНАРНЫЙ АНАЛИЗ · Консервативный / Базовый / Оптимистичный / Стресс
C2: КОНСЕРВАТИВНЫЙ | D2: БАЗОВЫЙ ★ | E2: ОПТИМИСТИЧНЫЙ | F2: СТРЕСС-ТЕСТ
B3: ЦЕНООБРАЗОВАНИЕ
B4: Цена/сотка фаза 1 (руб.) | C4: 70000 | D4: 85000 | E4: 100000 | F4: 60000
B5: Цена/сотка фаза 2 (руб.) | C5: 85000 | D5: 105000 | E5: 130000 | F5: 70000
B6: Цена/сотка фаза 3 (руб.) | C6: 100000 | D6: 125000 | E6: 160000 | F6: 80000
B7: Средняя цена/сотка (руб.) | C7: =(C4*18+C5*19+C6*18)/55 -> 85000 | D7: =(D4*18+D5*19+D6*18)/55 -> 105000 | E7: =(E4*18+E5*19+E6*18)/55 -> 130000 | F7: =(F4*18+F5*19+F6*18)/55 -> 70000
B8: ПРОДАЖИ
B9: Темп продаж (уч./год, ср.) | C9: 6 | D9: 11 | E9: 15 | F9: 4
B10: Срок реализации (лет) | C10: =ROUNDUP(55/C9,0) -> 10 | D10: =ROUNDUP(55/D9,0) -> 5 | E10: =ROUNDUP(55/E9,0) -> 4 | F10: =ROUNDUP(55/F9,0) -> 14
B11: ФИНАНСОВЫЕ РЕЗУЛЬТАТЫ
B12: Суммарная выручка (млн руб.) | C12: =55*15*C7/1000000 -> 70.125 | D12: =55*15*D7/1000000 -> 86.625 | E12: =55*15*E7/1000000 -> 107.25 | F12: =55*15*F7/1000000 -> 57.75
B13: Суммарный CAPEX+OPEX (млн руб.) | C13: 75 | D13: 75 | E13: 75 | F13: 90
B14: Чистая прибыль (млн руб.) | C14: =C12-C13 -> -4.875 | D14: =D12-D13 -> 11.625 | E14: =E12-E13 -> 32.25 | F14: =F12-F13 -> -32.25
B15: ROI | C15: =C14/C13 -> -0.065 | D15: =D14/D13 -> 0.155 | E15: =E14/E13 -> 0.43 | F15: =F14/F13 -> -0.35833333
B16: NPV @ 20% (млн руб.) | C16: =C14/1.2^3 -> -2.8211806 | D16: =D14/1.2^4 -> 5.6061921 | E16: =E14/1.2^3 -> 18.663194 | F16: =F14/1.2^5 -> -12.960552
B17: IRR (оценка) | C17: =C14/C13*0.8 -> -0.052 | D17: =D14/D13*0.9 -> 0.1395 | E17: =E14/E13 -> 0.43 | F17: =F14/F13*0.5 -> -0.17916667
B18: ВЫВОД

Sheet 4. Риски
B1: МАТРИЦА РИСКОВ · Стратегические / Операционные / Тактические
B2: Риск | C2: Тип | D2: Вероятность | E2: Влияние | F2: Описание & Триггер | G2: Митигация
B3: СТРАТЕГИЧЕСКИЕ РИСКИ
B4: Статус аренды (не собственность) | C4: Стратег. | D4: Высокая | E4: Критич. | F4: Покупатели частных домов требуют ИЖС в собственности. Риск заморозки продаж до перевода. Триггер: сделка сорвалась из-за статуса земли. | G4: Немедленно нанять земельных юристов. Бюджет ₽1,2 млн/год. Целевой срок перевода: 18 мес. Параллельно — продавать права аренды как промежуточный шаг.
B5: Отсутствие газификации | C5: Стратег. | D5: Высокая | E5: Критич. | F5: ИЖС без газа — потолок цены ограничен эконом+. Потеря 20–40% потенциальной выручки vs. газифицированных КП. Триггер: Bayside Residence снижает цены. | G5: Проработать подключение к газораспределительной сети через Можайск. ТЭО газификации в первый год. До газа — пропановые котлы как стандарт.
B6: Перенасыщение рынка Минского шоссе | C6: Стратег. | D6: Средняя | E6: Высокое | F6: 5+ активных КП в радиусе 30 км. При стагнации рынка продажи могут упасть до 3–4 уч./год. Триггер: ключевой конкурент объявляет акцию -20%. | G6: Дифференциация: заповедный лес — уникальное УТП. Фокус на эко-аудиторию. Партнёрство с экотуризмом Бородино.
B7: Снижение платёжеспособного спроса | C7: Стратег. | D7: Средняя | E7: Высокое | F7: Ипотечные ставки 20%+. Покупки загородки за наличные — нишевый рынок. Триггер: ключевая ставка ЦБ >20%. | G7: Рассрочка от ДНП (12 мес. без %). Партнёрство с банками по загородной ипотеке. Целевой сегмент: IT-специалисты и малый бизнес с кэшем.
B8: Изменение условий аренды Администрацией | C8: Стратег. | D8: Низкая | E8: Критич. | F8: Теоретически возможен пересмотр арендной ставки или отказ в переводе земли. Триггер: смена главы района. | G8: Зафиксировать все договорённости нотариально. Страхование инвестиций. Личные отношения с администрацией.
B9: ОПЕРАЦИОННЫЕ РИСКИ
B10: Рост стоимости строительства | C10: Операц. | D10: Высокая | E10: Высокое | F10: Инфляция стройматериалов 12–20%/год. Резерв 15% capex может не покрыть перерасход. Триггер: стоимость металлопроката выросла >30%. | G10: Заключить договоры с подрядчиками с фиксированной ценой. Резерв capex 15%. Приоритизация: сначала забор и КПП — продажный триггер.
B11: Задержки строительства инфраструктуры | C11: Операц. | D11: Средняя | E11: Высокое | F11: Каждый месяц задержки = потеря 1–2 продаж. При задержке 6 мес. — потеря ₽8–15 млн выручки. Триггер: подрядчик срывает сроки. | G11: Несколько параллельных подрядчиков. Штрафные санкции в договорах. Личный прораб на объекте.
B12: Конфликты внутри ДНП (38 существующих участников) | C12: Операц. | D12: Средняя | E12: Средн. | F12: Существующие члены ДНП могут блокировать решения об инфраструктуре или ценообразовании. Триггер: собрание срывает план застройки. | G12: Детальный устав ДНП с чёткими правилами голосования. Выкупить блокирующий пакет голосов. Коммуникационная программа для членов.
B13: Некачественное строительство и гарантийные риски | C13: Операц. | D13: Средняя | E13: Средн. | F13: Дефекты дорог, дренажа, электросетей после передачи жителям. Триггер: претензии первых 5 покупателей. | G13: Строительный контроль (технадзор). Гарантийный фонд 3% от каждой сделки. Качество = репутация = темп продаж фаз 2 и 3.
B14: ТАКТИЧЕСКИЕ РИСКИ
B15: Слабый маркетинг — недобор лидов | C15: Тактич. | D15: Средняя | E15: Высокое | F15: ЦИАН, Авито — высокая конкуренция. Стоимость лида в загородке: ₽5 000–25 000. Конверсия лид → сделка ~2–5%. Триггер: продаж < плана на 30%. | G15: Штатный маркетолог с KPI на лиды. Контент-маркетинг: YouTube-канал об экожизни. Агентская сеть (3% комиссия).
B16: Юридические претензии покупателей | C16: Тактич. | D16: Низкая | E16: Высокое | F16: Расторжение сделок, возврат денег, репутационный ущерб. Триггер: один громкий скандал в соцсетях. | G16: Прозрачные договоры. Escrow-счёт или аккредитив. Юрист в штате. Обязательное NPS-измерение после каждой сделки.
B17: Ошибки в кадастре / межевании | C17: Тактич. | D17: Низкая | E17: Средн. | F17: Пересечение границ участков, ошибки площади. Триггер: первый покупатель обнаруживает расхождение. | G17: Повторная проверка кадастровых паспортов всех 55 участков до старта продаж. Страхование титула.
B18: Сезонность продаж | C18: Тактич. | D18: Высокая | E18: Низкое | F18: 70% продаж загородки — март-июнь и сентябрь-октябрь. Зима — просадка выручки на 40–60%. | G18: Зимние акции и спецпредложения. Демонстрация заснеженного леса как эко-преимущества. Планирование CF с учётом сезонности.

Sheet 5. Принципы оценки
B1: ПРИНЦИПЫ ОЦЕНКИ ЗЕМЛИ ПОД МОСКВОЙ · Фреймворк топ-девелопера
B2: Критерий / Вопрос | C2: Оценка Эрмитаж | D2: Вес (из 10) | E2: Комментарий топ-девелопера
B3: 1. ЗЕМЛЯ И ПРАВОВОЙ СТАТУС
B4: Право собственности (не аренда)? | C4: 3/10 | D4: 8 | E4: Аренда 49 лет — приемлемо только как промежуточный шаг. Первое действие: перевод в ИЖС/собственность. Без этого дисконт 30–40% к рыночной цене.
B5: ВРИ: разрешено строительство дома? | C5: 7/10 | D5: 9 | E5: Нужен ВРИ «для ведения садоводства» или ИЖС. Дачный статус снижает ипотечную доступность.
B6: Обременения, залоги, судебные споры? | C6: 9/10 | D6: 9 | E6: Проверить ЕГРН, судебные базы, долги по аренде. Стоп-фактор #1.
B7: Кадастровая стоимость vs рыночная | C7: 7/10 | D7: 6 | E7: Дельта — потенциал оспаривания кадастровой стоимости для снижения налогов.
B8: 2. ЛОКАЦИЯ — THE GOLDEN RULE
B9: Расстояние от МКАД (золотая зона 60–90 км)? | C9: 5/10 | D9: 10 | E9: 100 км — за золотой зоной. Компенсируется заповедником. Минское шоссе — хорошая трасса без пробок.
B10: Транспортная доступность (ж/д, шоссе)? | C10: 6/10 | D10: 9 | E10: Нет ж/д. Только авто. Минус для части аудитории. Плюс: трасса М-1 без серьёзных пробок.
B11: Природное окружение (лес, вода)? | C11: 10/10 | D11: 9 | E11: Бородинский заповедник + Можайское водохранилище = топ-1 природный актив в зоне 100 км от МКАД.
B12: Конкурентное окружение (КП в 10 км)? | C12: 6/10 | D12: 8 | E12: Bayside Residence — сильный конкурент. Но в разном ценовом сегменте. Прямых аналогов с лесом нет.
B13: 3. ИНФРАСТРУКТУРА И КОММУНИКАЦИИ
B14: Газ — подведён или реализуем? | C14: 2/10 | D14: 10 | E14: Газ отсутствует. Это главный сдерживающий фактор ценообразования для ИЖС. Без газа — потолок 100–115 тыс./сотку.
B15: Электроснабжение (мощность)? | C15: 7/10 | D15: 9 | E15: ТП на объекте. Проверить выделенную мощность: ИЖС требует 15 кВт/участок.
B16: Дороги: асфальт или грунт? | C16: 4/10 | D16: 8 | E16: Грунтовые дороги внутри — неприемлемо для ИЖС. Асфальт — обязательный capex.
B17: Водоснабжение и канализация? | C17: 5/10 | D17: 7 | E17: Скважины на участках — стандарт. Септики — норма для загородки. Централизация нежелательна (дорого).
B18: 4. ЭКОНОМИКА СДЕЛКИ
B19: Цена входа (руб./сотка) vs рынок? | C19: 8/10 | D19: 10 | E19: Если актив берётся через выкуп прав аренды — возможна цена ₽15–25 тыс./сотку. Огромный апсайд к целевым 100–125 тыс.
B20: Потенциал прибыли >100% от инвестиций? | C20: 7/10 | D20: 10 | E20: В оптимистичном сценарии IRR > 50%. Базовый: ROI 80–100%. Проходит порог входа.
B21: Срок до выхода в кэш < 3 лет? | C21: 7/10 | D21: 9 | E21: При темпе 11 уч./год первые поступления — через 3–4 мес. после старта продаж.
B22: Стоимость инфраструктуры < 25% выручки? | C22: 6/10 | D22: 8 | E22: Capex ~₽50 млн / Выручка ~₽175 млн = 28%. Чуть выше. Риск capex-оверрана.
B23: 5. УТП И МАРКЕТИНГ
B24: Есть ли уникальное торговое преимущество? | C24: 9/10 | D24: 8 | E24: Да: заповедный лес по периметру + Бородинское поле = storytelling для премиального покупателя.
B25: Целевая аудитория чётко определена? | C25: 6/10 | D25: 7 | E25: IT-предприниматели 35–50 лет, экофamily, инвесторы в загородку. Платёжеспособны, покупают за кэш.
B26: Конкурентная цена входа для покупателя? | C26: 7/10 | D26: 8 | E26: В 2–3 раза дешевле Bayside. При том же природном активе. Это USP.
B27: ИТОГОВЫЙ БАЛЛ
B28: Эрмитаж — интегральная оценка | C28: 6.7/10 | E28: Проект проходит порог входа. Главные условия победы: 1) перевод земли в собственность, 2) газификация, 3) асфальт, 4) агрессивный маркетинг.

Sheet 6. Конкуренты
B1: КОНКУРЕНТНЫЙ АНАЛИЗ · Радиус 30 км от ДНП «Усадьба Эрмитаж»
B2: Поселок | C2: км от МКАД | D2: Расстояние | E2: Класс | F2: Цена/сотка мин | G2: Цена/сотка макс | H2: Инфраструктура | I2: Рейтинг
B3: ДНП «Усадьба Эрмитаж» ★ | C3: 100 | D3: 0 км | E3: ДНП/Эко | F3: 85000 | G3: 125000 | H3: Электр., дороги, КПП, заповедник | I3: ★★★★
B4: Bayside Residence | C4: 106 | D4: ~6 км | E4: Бизнес | F4: 188000 | G4: 350000 | H4: Газ, охрана, теннис, пляж, 360 домов | I4: ★★★★★
B5: КП «Речной» | C5: 95 | D5: ~12 км | E5: Эконом | F5: 45000 | G5: 70000 | H5: Электр., асфальт, дренаж, детск.пл. | I5: ★★★
B6: «Раточкины пруды» | C6: 85 | D6: ~20 км | E6: Эконом+ | F6: 60000 | G6: 80000 | H6: Газ, электр., бассейн, охрана, водоём | I6: ★★★★
B7: ДНП «Маринские дачи» | C7: 90 | D7: ~15 км | E7: ДНП | F7: 40000 | G7: 65000 | H7: Электр., грунтовые дороги | I7: ★★
B8: ДНП «Лыткинские зори» | C8: 98 | D8: ~5 км | E8: ДНП | F8: 50000 | G8: 80000 | H8: Электр., инфраструктура | I8: ★★★
B9: ИЖС рынок Можайский р-н | C9: 95 | D9: р-н | E9: Вторичка | F9: 30000 | G9: 157000 | H9: Варьируется, нет управления | I9: ★★★
B11: Вывод: «Усадьба Эрмитаж» — единственный объект с заповедным лесом по периметру в ценовом сегменте 85–125 тыс./сотку. Главный конкурент по природе (Bayside) стоит в 2–3 раза дороже.
